2021-06-13 12:35:41,108 | app.shortener | [INFO] : app.shortener | 58 | shortener | shortener.py | Base numbers generate are: [18]
2021-06-13 12:35:41,108 | app.shortener | [INFO] : app.shortener | 63 | shortener | shortener.py | The base sum is: 18.0
2021-06-13 12:35:41,108 | app.shortener | [INFO] : app.shortener | 73 | shortener | shortener.py | The url that is being sent back is https://www.youtube.com/results?search_query=ecommerce+flask+app+on+heroku
2021-06-13 12:39:15,362 | app.shortener | [INFO] : app.shortener | 58 | shortener | shortener.py | Base numbers generate are: [18]
2021-06-13 12:39:15,362 | app.shortener | [INFO] : app.shortener | 63 | shortener | shortener.py | The base sum is: 18.0
2021-06-13 12:39:15,363 | app.shortener | [INFO] : app.shortener | 73 | shortener | shortener.py | The url that is being sent back is https://www.youtube.com/results?search_query=ecommerce+flask+app+on+heroku
2021-06-13 12:42:22,344 | app.shortener | [INFO] : app.shortener | 39 | shortener | shortener.py | Adding it to the database
2021-06-13 12:42:59,578 | app.shortener | [INFO] : app.shortener | 39 | shortener | shortener.py | Adding it to the database
2021-06-13 12:42:59,584 | app.shortener | [INFO] : app.shortener | 41 | shortener | shortener.py | Added to the database
2021-06-13 12:42:59,584 | app.shortener | [INFO] : app.shortener | 44 | shortener | shortener.py | The shortened URL is k
2021-06-13 12:43:04,986 | app.shortener | [INFO] : app.shortener | 58 | shortener | shortener.py | Base numbers generate are: [20]
2021-06-13 12:43:04,986 | app.shortener | [INFO] : app.shortener | 63 | shortener | shortener.py | The base sum is: 20.0
2021-06-13 12:43:04,986 | app.shortener | [INFO] : app.shortener | 73 | shortener | shortener.py | The url that is being sent back is https://stackoverflow.com/questions/14132789/relative-imports-for-the-billionth-time
2021-06-13 12:48:23,905 | __main__ | [INFO] : __main__ | 36 | server | server.py | Index request received
2021-06-13 12:48:29,275 | __main__ | [INFO] : __main__ | 43 | server | server.py | URL received is https://stackoverflow.com/questions/22711087/flask-importerror-no-module-named-app
2021-06-13 12:48:29,542 | __main__ | [INFO] : __main__ | 61 | server | server.py | Sending back shortened Route
2021-06-13 12:49:03,571 | __main__ | [INFO] : __main__ | 66 | server | server.py | The code for the url is j
2021-06-13 12:49:03,572 | app.shortener | [INFO] : app.shortener | 58 | shortener | shortener.py | Base numbers generate are: [19]
2021-06-13 12:49:03,573 | app.shortener | [INFO] : app.shortener | 63 | shortener | shortener.py | The base sum is: 19.0
2021-06-13 12:49:03,573 | app.shortener | [INFO] : app.shortener | 73 | shortener | shortener.py | The url that is being sent back is https://stackoverflow.com/questions/22711087/flask-importerror-no-module-named-app
2021-06-13 12:49:03,575 | __main__ | [INFO] : __main__ | 83 | server | server.py | Redirecting to url https://stackoverflow.com/questions/22711087/flask-importerror-no-module-named-app
2021-06-13 12:56:34,764 | __main__ | [INFO] : __main__ | 36 | server | server.py | Index request received
2021-06-13 12:56:43,177 | __main__ | [INFO] : __main__ | 43 | server | server.py | URL received is https://www.youtube.com/results?search_query=ecommerce+flask+app+on+heroku
2021-06-13 12:56:43,412 | __main__ | [INFO] : __main__ | 61 | server | server.py | Sending back shortened Route
2021-06-13 12:56:50,996 | __main__ | [INFO] : __main__ | 66 | server | server.py | The code for the url is i
2021-06-13 12:56:50,997 | app.shortener | [INFO] : app.shortener | 59 | shortener | shortener.py | Base numbers generate are: [18]
2021-06-13 12:56:50,998 | app.shortener | [INFO] : app.shortener | 64 | shortener | shortener.py | The base sum is: 18.0
2021-06-13 12:56:50,999 | app.shortener | [INFO] : app.shortener | 74 | shortener | shortener.py | The url that is being sent back is https://www.youtube.com/results?search_query=ecommerce+flask+app+on+heroku
2021-06-13 12:56:51,001 | __main__ | [INFO] : __main__ | 83 | server | server.py | Redirecting to url https://www.youtube.com/results?search_query=ecommerce+flask+app+on+heroku
2021-06-13 12:57:09,674 | __main__ | [INFO] : __main__ | 43 | server | server.py | URL received is https://stackoverflow.com/questions/36189354/python-import-error-no-module-named-app
2021-06-13 12:57:09,678 | app.shortener | [INFO] : app.shortener | 41 | shortener | shortener.py | Adding it to the database
2021-06-13 12:57:09,687 | app.shortener | [INFO] : app.shortener | 43 | shortener | shortener.py | Added to the database
2021-06-13 12:57:09,688 | app.shortener | [INFO] : app.shortener | 46 | shortener | shortener.py | The shortened URL is l
2021-06-13 12:57:09,730 | __main__ | [INFO] : __main__ | 61 | server | server.py | Sending back shortened Route
2021-06-13 12:57:13,180 | __main__ | [INFO] : __main__ | 43 | server | server.py | URL received is https://stackoverflow.com/questions/36189354/python-import-error-no-module-named-app
2021-06-13 12:57:13,217 | __main__ | [INFO] : __main__ | 61 | server | server.py | Sending back shortened Route
2021-06-13 12:57:26,587 | __main__ | [INFO] : __main__ | 66 | server | server.py | The code for the url is l
2021-06-13 12:57:26,588 | app.shortener | [INFO] : app.shortener | 59 | shortener | shortener.py | Base numbers generate are: [21]
2021-06-13 12:57:26,588 | app.shortener | [INFO] : app.shortener | 64 | shortener | shortener.py | The base sum is: 21.0
2021-06-13 12:57:26,589 | app.shortener | [INFO] : app.shortener | 74 | shortener | shortener.py | The url that is being sent back is https://stackoverflow.com/questions/36189354/python-import-error-no-module-named-app
2021-06-13 12:57:26,590 | __main__ | [INFO] : __main__ | 83 | server | server.py | Redirecting to url https://stackoverflow.com/questions/36189354/python-import-error-no-module-named-app
2021-06-13 12:57:43,900 | __main__ | [INFO] : __main__ | 66 | server | server.py | The code for the url is 89g
2021-06-13 12:57:43,901 | app.shortener | [INFO] : app.shortener | 59 | shortener | shortener.py | Base numbers generate are: [16, 9, 8]
2021-06-13 12:57:43,901 | app.shortener | [INFO] : app.shortener | 64 | shortener | shortener.py | The base sum is: 31326.0
2021-06-13 12:57:43,906 | app.shortener | [ERROR] : app.shortener | 69 | shortener | shortener.py | The url is unknown
NoneType: None
2021-06-13 12:57:43,907 | __main__ | [ERROR] : __main__ | 73 | server | server.py | The following Exception has happened: URL is unknown
Traceback (most recent call last):
  File "C:\Users\sherwin\projects\UrlShortener\server.py", line 70, in resolveUrl
    resolved_url = Shortener.resolve(code)
  File "C:\Users\sherwin\projects\UrlShortener\app\shortener.py", line 70, in resolve
    raise Exception("URL is unknown")
Exception: URL is unknown
2021-06-13 12:57:43,910 | __main__ | [INFO] : __main__ | 77 | server | server.py | Sending back error html as URL wasn't found
2021-06-13 13:07:48,433 | __main__ | [INFO] : __main__ | 36 | server | server.py | Index request received
2021-06-13 13:07:53,682 | __main__ | [INFO] : __main__ | 43 | server | server.py | URL received is https://stackoverflow.com/questions/35918605/how-to-delete-a-table-in-sqlalchemy
2021-06-13 13:07:53,683 | util.models | [ERROR] : util.models | 21 | models | models.py | Failed to verify the url in db becuase: 'NoneType' object has no attribute 'drivername'
Traceback (most recent call last):
  File "C:\Users\sherwin\AppData\Local\Programs\Python\Python37\lib\site-packages\sqlalchemy\util\_collections.py", line 1008, in __call__
    return self.registry[key]
KeyError: <greenlet.greenlet object at 0x0000020F7421A3B8 (otid=0x0000020F741DE0E8) current active started main>

During handling of the above exception, another exception occurred:

Traceback (most recent call last):
  File "C:\Users\sherwin\projects\UrlShortener\util\models.py", line 18, in check_url
    count = db.session.query(TinnieRepository).filter(TinnieRepository.url == query_url).count()
  File "<string>", line 2, in query
  File "C:\Users\sherwin\AppData\Local\Programs\Python\Python37\lib\site-packages\sqlalchemy\orm\scoping.py", line 105, in _proxied
    return self.registry()
  File "C:\Users\sherwin\AppData\Local\Programs\Python\Python37\lib\site-packages\sqlalchemy\util\_collections.py", line 1010, in __call__
    return self.registry.setdefault(key, self.createfunc())
  File "C:\Users\sherwin\AppData\Local\Programs\Python\Python37\lib\site-packages\sqlalchemy\orm\session.py", line 4101, in __call__
    return self.class_(**local_kw)
  File "C:\Users\sherwin\AppData\Local\Programs\Python\Python37\lib\site-packages\flask_sqlalchemy\__init__.py", line 176, in __init__
    bind = options.pop('bind', None) or db.engine
  File "C:\Users\sherwin\AppData\Local\Programs\Python\Python37\lib\site-packages\flask_sqlalchemy\__init__.py", line 998, in engine
    return self.get_engine()
  File "C:\Users\sherwin\AppData\Local\Programs\Python\Python37\lib\site-packages\flask_sqlalchemy\__init__.py", line 1017, in get_engine
    return connector.get_engine()
  File "C:\Users\sherwin\AppData\Local\Programs\Python\Python37\lib\site-packages\flask_sqlalchemy\__init__.py", line 593, in get_engine
    sa_url, options = self.get_options(sa_url, echo)
  File "C:\Users\sherwin\AppData\Local\Programs\Python\Python37\lib\site-packages\flask_sqlalchemy\__init__.py", line 608, in get_options
    sa_url, options = self._sa.apply_driver_hacks(self._app, sa_url, options)
  File "C:\Users\sherwin\AppData\Local\Programs\Python\Python37\lib\site-packages\flask_sqlalchemy\__init__.py", line 933, in apply_driver_hacks
    if sa_url.drivername.startswith('mysql'):
AttributeError: 'NoneType' object has no attribute 'drivername'
2021-06-13 13:07:53,714 | __main__ | [ERROR] : __main__ | 55 | server | server.py | The following Exception just happened: Failed to verify the url in db becuase: 'NoneType' object has no attribute 'drivername'
Traceback (most recent call last):
  File "C:\Users\sherwin\AppData\Local\Programs\Python\Python37\lib\site-packages\sqlalchemy\util\_collections.py", line 1008, in __call__
    return self.registry[key]
KeyError: <greenlet.greenlet object at 0x0000020F7421A3B8 (otid=0x0000020F741DE0E8) current active started main>

During handling of the above exception, another exception occurred:

Traceback (most recent call last):
  File "C:\Users\sherwin\projects\UrlShortener\util\models.py", line 18, in check_url
    count = db.session.query(TinnieRepository).filter(TinnieRepository.url == query_url).count()
  File "<string>", line 2, in query
  File "C:\Users\sherwin\AppData\Local\Programs\Python\Python37\lib\site-packages\sqlalchemy\orm\scoping.py", line 105, in _proxied
    return self.registry()
  File "C:\Users\sherwin\AppData\Local\Programs\Python\Python37\lib\site-packages\sqlalchemy\util\_collections.py", line 1010, in __call__
    return self.registry.setdefault(key, self.createfunc())
  File "C:\Users\sherwin\AppData\Local\Programs\Python\Python37\lib\site-packages\sqlalchemy\orm\session.py", line 4101, in __call__
    return self.class_(**local_kw)
  File "C:\Users\sherwin\AppData\Local\Programs\Python\Python37\lib\site-packages\flask_sqlalchemy\__init__.py", line 176, in __init__
    bind = options.pop('bind', None) or db.engine
  File "C:\Users\sherwin\AppData\Local\Programs\Python\Python37\lib\site-packages\flask_sqlalchemy\__init__.py", line 998, in engine
    return self.get_engine()
  File "C:\Users\sherwin\AppData\Local\Programs\Python\Python37\lib\site-packages\flask_sqlalchemy\__init__.py", line 1017, in get_engine
    return connector.get_engine()
  File "C:\Users\sherwin\AppData\Local\Programs\Python\Python37\lib\site-packages\flask_sqlalchemy\__init__.py", line 593, in get_engine
    sa_url, options = self.get_options(sa_url, echo)
  File "C:\Users\sherwin\AppData\Local\Programs\Python\Python37\lib\site-packages\flask_sqlalchemy\__init__.py", line 608, in get_options
    sa_url, options = self._sa.apply_driver_hacks(self._app, sa_url, options)
  File "C:\Users\sherwin\AppData\Local\Programs\Python\Python37\lib\site-packages\flask_sqlalchemy\__init__.py", line 933, in apply_driver_hacks
    if sa_url.drivername.startswith('mysql'):
AttributeError: 'NoneType' object has no attribute 'drivername'

During handling of the above exception, another exception occurred:

Traceback (most recent call last):
  File "C:\Users\sherwin\projects\UrlShortener\server.py", line 51, in shortenUrl
    url = Shortener.shorten(url)
  File "C:\Users\sherwin\projects\UrlShortener\util\shortener.py", line 35, in shorten
    elif models.check_url(url):
  File "C:\Users\sherwin\projects\UrlShortener\util\models.py", line 22, in check_url
    raise Exception(f"Failed to verify the url in db becuase: {e}")
Exception: Failed to verify the url in db becuase: 'NoneType' object has no attribute 'drivername'
2021-06-13 13:07:53,720 | __main__ | [INFO] : __main__ | 58 | server | server.py | Sending Back Exception report
2021-06-13 13:08:44,262 | __main__ | [INFO] : __main__ | 36 | server | server.py | Index request received
2021-06-13 13:08:49,790 | __main__ | [INFO] : __main__ | 43 | server | server.py | URL received is https://github.com/pallets/flask/blob/main/src/flask/logging.py
2021-06-13 13:08:49,850 | util.shortener | [INFO] : util.shortener | 41 | shortener | shortener.py | Adding it to the database
2021-06-13 13:08:49,855 | util.shortener | [INFO] : util.shortener | 43 | shortener | shortener.py | Added to the database
2021-06-13 13:08:49,856 | util.shortener | [INFO] : util.shortener | 46 | shortener | shortener.py | The shortened URL is m
2021-06-13 13:08:49,875 | __main__ | [INFO] : __main__ | 61 | server | server.py | Sending back shortened Route
2021-06-13 13:08:54,090 | __main__ | [INFO] : __main__ | 66 | server | server.py | The code for the url is m
2021-06-13 13:08:54,090 | util.shortener | [INFO] : util.shortener | 59 | shortener | shortener.py | Base numbers generate are: [22]
2021-06-13 13:08:54,091 | util.shortener | [INFO] : util.shortener | 64 | shortener | shortener.py | The base sum is: 22.0
2021-06-13 13:08:54,091 | util.shortener | [INFO] : util.shortener | 74 | shortener | shortener.py | The url that is being sent back is https://github.com/pallets/flask/blob/main/src/flask/logging.py
2021-06-13 13:08:54,092 | __main__ | [INFO] : __main__ | 83 | server | server.py | Redirecting to url https://github.com/pallets/flask/blob/main/src/flask/logging.py
2021-06-13 13:09:03,224 | __main__ | [INFO] : __main__ | 66 | server | server.py | The code for the url is ddfs
2021-06-13 13:09:03,225 | util.shortener | [INFO] : util.shortener | 59 | shortener | shortener.py | Base numbers generate are: [28, 15, 13, 13]
2021-06-13 13:09:03,225 | util.shortener | [INFO] : util.shortener | 64 | shortener | shortener.py | The base sum is: 3149194.0
2021-06-13 13:09:03,227 | util.shortener | [ERROR] : util.shortener | 69 | shortener | shortener.py | The url is unknown
NoneType: None
2021-06-13 13:09:03,228 | __main__ | [ERROR] : __main__ | 73 | server | server.py | The following Exception has happened: URL is unknown
Traceback (most recent call last):
  File "C:\Users\sherwin\projects\UrlShortener\server.py", line 70, in resolveUrl
    resolved_url = Shortener.resolve(code)
  File "C:\Users\sherwin\projects\UrlShortener\util\shortener.py", line 70, in resolve
    raise Exception("URL is unknown")
Exception: URL is unknown
2021-06-13 13:09:03,230 | __main__ | [INFO] : __main__ | 77 | server | server.py | Sending back error html as URL wasn't found
